Workbook
Name Slicer_Months__NGÀY_CHI: #N/A

Sheet Dashboard
V14: Lựa chọn 👉 | W14: Tất cả
U15: TOP | V15: Khoản chi tiêu | W15: Số tiền | X15: Ngày
U16: 1 | V16: ='Công thức'!V3 -> Nhà ở | W16: ='Công thức'!W3 -> 500000 | X16: ='Công thức'!S3 -> 45962
U17: 2 | V17: ='Công thức'!V4 -> Nhà ở | W17: ='Công thức'!W4 -> 500000 | X17: ='Công thức'!S4 -> 45975
U18: 3 | V18: ='Công thức'!V5 -> Gửi tiết kiệm | W18: ='Công thức'!W5 -> 500000 | X18: ='Công thức'!S5 -> 45965
U19: 4 | V19: ='Công thức'!V6 -> Quỹ du lịch | W19: ='Công thức'!W6 -> 500000 | X19: ='Công thức'!S6 -> 45967
U20: 5 | V20: ='Công thức'!V7 -> Mua cổ phiếu | W20: ='Công thức'!W7 -> 500000 | X20: ='Công thức'!S7 -> 45969
U21: 6 | V21: ='Công thức'!V8 -> Mua cổ phiếu | W21: ='Công thức'!W8 -> 500000 | X21: ='Công thức'!S8 -> 45971
U22: 7 | V22: ='Công thức'!V9 -> Đám cưới đồng nghiệp | W22: ='Công thức'!W9 -> 500000 | X22: ='Công thức'!S9 -> 45982
U23: 8 | V23: ='Công thức'!V10 -> Tiền điện | W23: ='Công thức'!W10 -> 409000 | X23: ='Công thức'!S10 -> 45964
U24: 9 | V24: ='Công thức'!V11 -> Quà tặng người yêu | W24: ='Công thức'!W11 -> 300000 | X24: ='Công thức'!S11 -> 45983
U25: 10 | V25: ='Công thức'!V12 -> Mua sách kế toán doanh nghiệp | W25: ='Công thức'!W12 -> 292000 | X25: ='Công thức'!S12 -> 45963

Sheet Công thức
A1: Xác định ngày tháng hiện tại | D1: Tỉ trọng các nhóm chi tiêu | G1: Năm theo dõi, lấy theo bảng chi tiêu | J1: =YEAR(MAX(Table10[NGÀY CHI])) -> 2025 | L1: Chi tiêu của tháng hiện tại so với định mức | S1: Lấy ra TOP 10 các khoản chi tiêu | W1: =Dashboard!W14 -> Tất cả | Y1: So sánh chi tiêu theo từng ngày của tháng này với tháng trước | AD1: Lấy chi tiêu thực tế của từng loại chi tiêu theo từng tháng | AJ1: Lấy ra TOP 5 loại chi tiêu của các tháng có chi tiêu dưới định mức
A2: ThisMonth | B2: LastMonth | D2: Nhóm chi tiêu | E2: Tổng tiền | G2: STT | H2: Tháng | I2: Tổng chi tiêu | J2: Tổng thu nhập | L2: Nhóm chi tiêu | M2: Định mức chi tiêu | N2: Chi tiêu thực tế | O2: Chênh lệch | P2: Định mức | Q2: Tỉ lệ chi tiêu | S2: NGÀY CHI | T2: NHÓM CHI TIÊU | U2: LOẠI CHI TIÊU | V2: CHI TIẾT | W2: SỐ TIỀN | Y2: Tháng này | Z2: Tháng trước | AA2: Chi tiêu tháng này | AB2: Chi tiêu tháng trước | AD2: LOẠI CHI TIÊU | AE2: Months (NGÀY CHI) | AF2: Sum of SỐ TIỀN | AG2: Định mức | AH2: Chênh lệch | AJ2: Loại chi tiêu | AK2: Tháng | AL2: Chi tiêu | AM2: Định mức | AN2: Số dư
A3: =DATE(YEAR(A4),MONTH(A4),1) -> 45962 | B3: =DATE(YEAR(A3),MONTH(A3)-1,1) -> 45931 | D3: =D10 -> Chi phí thiết yếu | E3: =E10 -> 2900000 | G3: 1 | H3: =DATEVALUE(Table8[[#This Row],[STT]]&"/"&$J$1) -> 45658 | I3: =SUMIFS(Table10[SỐ TIỀN],Table10[NGÀY CHI],">="&Table8[[#This Row],[Tháng]],Table10[NGÀY CHI],"<"&H4) -> 8934000 | J3: =IF(Table8[[#This Row],[Tổng chi tiêu]]<>0,SUMIFS(Table103[SỐ TIỀN],Table103[NGÀY],">="&Table8[[#This Row],[Tháng]],Table103[NGÀY],"<"&H4),NA()) -> 9900000 | L3: Tất cả | M3: =SUM(M4:M8) -> 10000000 | N3: =SUMIFS(Table10[SỐ TIỀN],Table10[NGÀY CHI],">="&$A$3) -> 7965000 | O3: =M3-N3 -> 2035000 | P3: 1 | Q3: =N3/M3 -> 0.7965 | S3: {=_xlfn.TAKE(_xlfn.SORTBY(_xlfn.ANCHORARRAY(S16),INDEX(_xlfn.ANCHORARRAY(S16),,5),-1),10)} -> 45962 | T3: Chi phí thiết yếu | U3: Nhà ở | V3: Nhà ở | W3: 500000 | Y3: =A3 -> 45962 | Z3: =B3 -> 45931 | AA3: =IF(Table13[[#This Row],[Tháng này]]<=$A$4,SUMIFS(Table10[SỐ TIỀN],Table10[NGÀY CHI],Table13[[#This Row],[Tháng này]]),NA()) -> 535000 | AB3: =SUMIFS(Table10[SỐ TIỀN],Table10[NGÀY CHI],Table13[[#This Row],[Tháng trước]]) -> 536000 | AD3: Ăn uống | AE3: Jan | AF3: 1905000 | AG3: =IFERROR(VLOOKUP(AD3,_xlfn.VSTACK(Table1[],Table14[],Table16[],Table18[],Table110[]),2,0),0) -> 2000000 | AH3: =AG3-AF3 -> 95000 | AJ3: {=_xlfn.TAKE(_xlfn.SORTBY(AD3:AH500,AH3:AH500,-1),5)} -> Ăn uống | AK3: Nov | AL3: 1215000 | AM3: 2000000 | AN3: 785000
A4: =MAX(Table10[NGÀY CHI]) -> 45983 | B4: =EOMONTH(B3,0) -> 45961 | D4: =D11 -> Chi phí cá nhân | E4: =E11 -> 2619000 | G4: 2 | H4: =DATEVALUE(Table8[[#This Row],[STT]]&"/"&$J$1) -> 45689 | I4: =SUMIFS(Table10[SỐ TIỀN],Table10[NGÀY CHI],">="&Table8[[#This Row],[Tháng]],Table10[NGÀY CHI],"<"&H5) -> 9536000 | J4: =IF(Table8[[#This Row],[Tổng chi tiêu]]<>0,SUMIFS(Table103[SỐ TIỀN],Table103[NGÀY],">="&Table8[[#This Row],[Tháng]],Table103[NGÀY],"<"&H5),NA()) -> 11100000 | L4: {=_xlfn.UNIQUE(_xlfn.ANCHORARRAY('Định mức'!E31))} -> Chi phí thiết yếu | M4: =Table1[[#Totals],[Định mức]] -> 3000000 | N4: =VLOOKUP(L4,Table6[],2,0) -> 2900000 | O4: =M4-N4 -> 100000 | P4: 1 | Q4: =N4/M4 -> 0.96666667 | S4: 45975 | T4: Chi phí thiết yếu | U4: Nhà ở | V4: Nhà ở | W4: 500000 | Y4: =Y3+1 -> 45963 | Z4: =Z3+1 -> 45932 | AA4: =IF(Table13[[#This Row],[Tháng này]]<=$A$4,SUMIFS(Table10[SỐ TIỀN],Table10[NGÀY CHI],Table13[[#This Row],[Tháng này]]),NA()) -> 449000 | AB4: =SUMIFS(Table10[SỐ TIỀN],Table10[NGÀY CHI],Table13[[#This Row],[Tháng trước]]) -> 563000 | AD4: Ăn uống | AE4: Feb | AF4: 1848000 | AG4: =IFERROR(VLOOKUP(AD4,_xlfn.VSTACK(Table1[],Table14[],Table16[],Table18[],Table110[]),2,0),0) -> 2000000 | AH4: =AG4-AF4 -> 152000 | AJ4: Nhà ở | AK4: Oct | AL4: 1000000 | AM4: 1600000 | AN4: 600000
D5: =D12 -> Giải trí và xã hội | E5: =E12 -> 1765000 | G5: 3 | H5: =DATEVALUE(Table8[[#This Row],[STT]]&"/"&$J$1) -> 45717 | I5: =SUMIFS(Table10[SỐ TIỀN],Table10[NGÀY CHI],">="&Table8[[#This Row],[Tháng]],Table10[NGÀY CHI],"<"&H6) -> 10991000 | J5: =IF(Table8[[#This Row],[Tổng chi tiêu]]<>0,SUMIFS(Table103[SỐ TIỀN],Table103[NGÀY],">="&Table8[[#This Row],[Tháng]],Table103[NGÀY],"<"&H6),NA()) -> 10000000 | L5: Chi phí cá nhân | M5: =Table14[[#Totals],[Định mức]] -> 2800000 | N5: =VLOOKUP(L5,Table6[],2,0) -> 2619000 | O5: =M5-N5 -> 181000 | P5: 1 | Q5: =N5/M5 -> 0.93535714 | S5: 45965 | T5: Tiết kiệm, đầu tư | U5: Tiết kiệm | V5: Gửi tiết kiệm | W5: 500000 | Y5: =Y4+1 -> 45964 | Z5: =Z4+1 -> 45933 | AA5: =IF(Table13[[#This Row],[Tháng này]]<=$A$4,SUMIFS(Table10[SỐ TIỀN],Table10[NGÀY CHI],Table13[[#This Row],[Tháng này]]),NA()) -> 595000 | AB5: =SUMIFS(Table10[SỐ TIỀN],Table10[NGÀY CHI],Table13[[#This Row],[Tháng trước]]) -> 642000 | AD5: Ăn uống | AE5: Mar | AF5: 2274000 | AG5: =IFERROR(VLOOKUP(AD5,_xlfn.VSTACK(Table1[],Table14[],Table16[],Table18[],Table110[]),2,0),0) -> 2000000 | AH5: =AG5-AF5 -> -274000 | AJ5: Nhà ở | AK5: Nov | AL5: 1000000 | AM5: 1600000 | AN5: 600000
D6: =D13 -> Tiết kiệm, đầu tư | E6: =E13 -> 1500000 | G6: 4 | H6: =DATEVALUE(Table8[[#This Row],[STT]]&"/"&$J$1) -> 45748 | I6: =SUMIFS(Table10[SỐ TIỀN],Table10[NGÀY CHI],">="&Table8[[#This Row],[Tháng]],Table10[NGÀY CHI],"<"&H7) -> 10715000 | J6: =IF(Table8[[#This Row],[Tổng chi tiêu]]<>0,SUMIFS(Table103[SỐ TIỀN],Table103[NGÀY],">="&Table8[[#This Row],[Tháng]],Table103[NGÀY],"<"&H7),NA()) -> 12100000 | L6: Giải trí và xã hội | M6: =Table16[[#Totals],[Định mức]] -> 1900000 | N6: =VLOOKUP(L6,Table6[],2,0) -> 1765000 | O6: =M6-N6 -> 135000 | P6: 1 | Q6: =N6/M6 -> 0.92894737 | S6: 45967 | T6: Giải trí và xã hội | U6: Du lịch | V6: Quỹ du lịch | W6: 500000 | Y6: =Y5+1 -> 45965 | Z6: =Z5+1 -> 45934 | AA6: =IF(Table13[[#This Row],[Tháng này]]<=$A$4,SUMIFS(Table10[SỐ TIỀN],Table10[NGÀY CHI],Table13[[#This Row],[Tháng này]]),NA()) -> 638000 | AB6: =SUMIFS(Table10[SỐ TIỀN],Table10[NGÀY CHI],Table13[[#This Row],[Tháng trước]]) -> 147000 | AD6: Ăn uống | AE6: Apr | AF6: 2225000 | AG6: =IFERROR(VLOOKUP(AD6,_xlfn.VSTACK(Table1[],Table14[],Table16[],Table18[],Table110[]),2,0),0) -> 2000000 | AH6: =AG6-AF6 -> -225000 | AJ6: Giải trí | AK6: Mar | AL6: 245000 | AM6: 500000 | AN6: 255000
D7: =D14 -> Quà tặng, hiếu, hỉ | E7: =E14 -> 150000 | G7: 5 | H7: =DATEVALUE(Table8[[#This Row],[STT]]&"/"&$J$1) -> 45778 | I7: =SUMIFS(Table10[SỐ TIỀN],Table10[NGÀY CHI],">="&Table8[[#This Row],[Tháng]],Table10[NGÀY CHI],"<"&H8) -> 9829000 | J7: =IF(Table8[[#This Row],[Tổng chi tiêu]]<>0,SUMIFS(Table103[SỐ TIỀN],Table103[NGÀY],">="&Table8[[#This Row],[Tháng]],Table103[NGÀY],"<"&H8),NA()) -> 10000000 | L7: Tiết kiệm, đầu tư | M7: =Table18[[#Totals],[Định mức]] -> 1500000 | N7: =VLOOKUP(L7,Table6[],2,0) -> 1500000 | O7: =M7-N7 -> 0 | P7: 1 | Q7: =N7/M7 -> 1 | S7: 45969 | T7: Tiết kiệm, đầu tư | U7: Đầu tư | V7: Mua cổ phiếu | W7: 500000 | Y7: =Y6+1 -> 45966 | Z7: =Z6+1 -> 45935 | AA7: =IF(Table13[[#This Row],[Tháng này]]<=$A$4,SUMIFS(Table10[SỐ TIỀN],Table10[NGÀY CHI],Table13[[#This Row],[Tháng này]]),NA()) -> 245000 | AB7: =SUMIFS(Table10[SỐ TIỀN],Table10[NGÀY CHI],Table13[[#This Row],[Tháng trước]]) -> 650000 | AD7: Ăn uống | AE7: May | AF7: 2187000 | AG7: =IFERROR(VLOOKUP(AD7,_xlfn.VSTACK(Table1[],Table14[],Table16[],Table18[],Table110[]),2,0),0) -> 2000000 | AH7: =AG7-AF7 -> -187000 | AJ7: Học tập, phát triển | AK7: May | AL7: 271000 | AM7: 500000 | AN7: 229000
G8: 6 | H8: =DATEVALUE(Table8[[#This Row],[STT]]&"/"&$J$1) -> 45809 | I8: =SUMIFS(Table10[SỐ TIỀN],Table10[NGÀY CHI],">="&Table8[[#This Row],[Tháng]],Table10[NGÀY CHI],"<"&H9) -> 9994000 | J8: =IF(Table8[[#This Row],[Tổng chi tiêu]]<>0,SUMIFS(Table103[SỐ TIỀN],Table103[NGÀY],">="&Table8[[#This Row],[Tháng]],Table103[NGÀY],"<"&H9),NA()) -> 11200000 | L8: Quà tặng, hiếu, hỉ | M8: =Table110[[#Totals],[Định mức]] -> 800000 | N8: =VLOOKUP(L8,Table6[],2,0) -> 150000 | O8: =M8-N8 -> 650000 | P8: 1 | Q8: =N8/M8 -> 0.1875 | S8: 45971 | T8: Tiết kiệm, đầu tư | U8: Đầu tư | V8: Mua cổ phiếu | W8: 500000 | Y8: =Y7+1 -> 45967 | Z8: =Z7+1 -> 45936 | AA8: =IF(Table13[[#This Row],[Tháng này]]<=$A$4,SUMIFS(Table10[SỐ TIỀN],Table10[NGÀY CHI],Table13[[#This Row],[Tháng này]]),NA()) -> 547000 | AB8: =SUMIFS(Table10[SỐ TIỀN],Table10[NGÀY CHI],Table13[[#This Row],[Tháng trước]]) -> 552000 | AD8: Ăn uống | AE8: Jun | AF8: 2193000 | AG8: =IFERROR(VLOOKUP(AD8,_xlfn.VSTACK(Table1[],Table14[],Table16[],Table18[],Table110[]),2,0),0) -> 2000000 | AH8: =AG8-AF8 -> -193000
D9: Row Labels | E9: Sum of SỐ TIỀN | G9: 7 | H9: =DATEVALUE(Table8[[#This Row],[STT]]&"/"&$J$1) -> 45839 | I9: =SUMIFS(Table10[SỐ TIỀN],Table10[NGÀY CHI],">="&Table8[[#This Row],[Tháng]],Table10[NGÀY CHI],"<"&H10) -> 12842000 | J9: =IF(Table8[[#This Row],[Tổng chi tiêu]]<>0,SUMIFS(Table103[SỐ TIỀN],Table103[NGÀY],">="&Table8[[#This Row],[Tháng]],Table103[NGÀY],"<"&H10),NA()) -> 13000000 | S9: 45982 | T9: Quà tặng, hiếu, hỉ | U9: Hiếu, hỉ | V9: Đám cưới đồng nghiệp | W9: 500000 | Y9: =Y8+1 -> 45968 | Z9: =Z8+1 -> 45937 | AA9: =IF(Table13[[#This Row],[Tháng này]]<=$A$4,SUMIFS(Table10[SỐ TIỀN],Table10[NGÀY CHI],Table13[[#This Row],[Tháng này]]),NA()) -> 445000 | AB9: =SUMIFS(Table10[SỐ TIỀN],Table10[NGÀY CHI],Table13[[#This Row],[Tháng trước]]) -> 455000 | AD9: Ăn uống | AE9: Jul | AF9: 2316000 | AG9: =IFERROR(VLOOKUP(AD9,_xlfn.VSTACK(Table1[],Table14[],Table16[],Table18[],Table110[]),2,0),0) -> 2000000 | AH9: =AG9-AF9 -> -316000
D10: Chi phí thiết yếu | E10: 2900000 | G10: 8 | H10: =DATEVALUE(Table8[[#This Row],[STT]]&"/"&$J$1) -> 45870 | I10: =SUMIFS(Table10[SỐ TIỀN],Table10[NGÀY CHI],">="&Table8[[#This Row],[Tháng]],Table10[NGÀY CHI],"<"&H11) -> 9838000 | J10: =IF(Table8[[#This Row],[Tổng chi tiêu]]<>0,SUMIFS(Table103[SỐ TIỀN],Table103[NGÀY],">="&Table8[[#This Row],[Tháng]],Table103[NGÀY],"<"&H11),NA()) -> 9900000 | S10: 45964 | T10: Chi phí thiết yếu | U10: Hóa đơn hàng tháng | V10: Tiền điện | W10: 409000 | Y10: =Y9+1 -> 45969 | Z10: =Z9+1 -> 45938 | AA10: =IF(Table13[[#This Row],[Tháng này]]<=$A$4,SUMIFS(Table10[SỐ TIỀN],Table10[NGÀY CHI],Table13[[#This Row],[Tháng này]]),NA()) -> 551000 | AB10: =SUMIFS(Table10[SỐ TIỀN],Table10[NGÀY CHI],Table13[[#This Row],[Tháng trước]]) -> 202000 | AD10: Ăn uống | AE10: Aug | AF10: 2287000 | AG10: =IFERROR(VLOOKUP(AD10,_xlfn.VSTACK(Table1[],Table14[],Table16[],Table18[],Table110[]),2,0),0) -> 2000000 | AH10: =AG10-AF10 -> -287000
D11: Chi phí cá nhân | E11: 2619000 | G11: 9 | H11: =DATEVALUE(Table8[[#This Row],[STT]]&"/"&$J$1) -> 45901 | I11: =SUMIFS(Table10[SỐ TIỀN],Table10[NGÀY CHI],">="&Table8[[#This Row],[Tháng]],Table10[NGÀY CHI],"<"&H12) -> 10518000 | J11: =IF(Table8[[#This Row],[Tổng chi tiêu]]<>0,SUMIFS(Table103[SỐ TIỀN],Table103[NGÀY],">="&Table8[[#This Row],[Tháng]],Table103[NGÀY],"<"&H12),NA()) -> 10500000 | S11: 45983 | T11: Quà tặng, hiếu, hỉ | U11: Quà tặng | V11: Quà tặng người yêu | W11: 300000 | Y11: =Y10+1 -> 45970 | Z11: =Z10+1 -> 45939 | AA11: =IF(Table13[[#This Row],[Tháng này]]<=$A$4,SUMIFS(Table10[SỐ TIỀN],Table10[NGÀY CHI],Table13[[#This Row],[Tháng này]]),NA()) -> 154000 | AB11: =SUMIFS(Table10[SỐ TIỀN],Table10[NGÀY CHI],Table13[[#This Row],[Tháng trước]]) -> 162000 | AD11: Ăn uống | AE11: Sep | AF11: 2211000 | AG11: =IFERROR(VLOOKUP(AD11,_xlfn.VSTACK(Table1[],Table14[],Table16[],Table18[],Table110[]),2,0),0) -> 2000000 | AH11: =AG11-AF11 -> -211000
D12: Giải trí và xã hội | E12: 1765000 | G12: 10 | H12: =DATEVALUE(Table8[[#This Row],[STT]]&"/"&$J$1) -> 45931 | I12: =SUMIFS(Table10[SỐ TIỀN],Table10[NGÀY CHI],">="&Table8[[#This Row],[Tháng]],Table10[NGÀY CHI],"<"&H13) -> 9178000 | J12: =IF(Table8[[#This Row],[Tổng chi tiêu]]<>0,SUMIFS(Table103[SỐ TIỀN],Table103[NGÀY],">="&Table8[[#This Row],[Tháng]],Table103[NGÀY],"<"&H13),NA()) -> 10200000 | S12: 45963 | T12: Chi phí cá nhân | U12: Học tập, phát triển | V12: Mua sách kế toán doanh nghiệp | W12: 292000 | Y12: =Y11+1 -> 45971 | Z12: =Z11+1 -> 45940 | AA12: =IF(Table13[[#This Row],[Tháng này]]<=$A$4,SUMIFS(Table10[SỐ TIỀN],Table10[NGÀY CHI],Table13[[#This Row],[Tháng này]]),NA()) -> 553000 | AB12: =SUMIFS(Table10[SỐ TIỀN],Table10[NGÀY CHI],Table13[[#This Row],[Tháng trước]]) -> 556000 | AD12: Ăn uống | AE12: Oct | AF12: 1987000 | AG12: =IFERROR(VLOOKUP(AD12,_xlfn.VSTACK(Table1[],Table14[],Table16[],Table18[],Table110[]),2,0),0) -> 2000000 | AH12: =AG12-AF12 -> 13000
D13: Tiết kiệm, đầu tư | E13: 1500000 | G13: 11 | H13: =DATEVALUE(Table8[[#This Row],[STT]]&"/"&$J$1) -> 45962 | I13: =SUMIFS(Table10[SỐ TIỀN],Table10[NGÀY CHI],">="&Table8[[#This Row],[Tháng]],Table10[NGÀY CHI],"<"&H14) -> 7965000 | J13: =IF(Table8[[#This Row],[Tổng chi tiêu]]<>0,SUMIFS(Table103[SỐ TIỀN],Table103[NGÀY],">="&Table8[[#This Row],[Tháng]],Table103[NGÀY],"<"&H14),NA()) -> 10000000 | Y13: =Y12+1 -> 45972 | Z13: =Z12+1 -> 45941 | AA13: =IF(Table13[[#This Row],[Tháng này]]<=$A$4,SUMIFS(Table10[SỐ TIỀN],Table10[NGÀY CHI],Table13[[#This Row],[Tháng này]]),NA()) -> 425000 | AB13: =SUMIFS(Table10[SỐ TIỀN],Table10[NGÀY CHI],Table13[[#This Row],[Tháng trước]]) -> 447000 | AD13: Ăn uống | AE13: Nov | AF13: 1215000 | AG13: =IFERROR(VLOOKUP(AD13,_xlfn.VSTACK(Table1[],Table14[],Table16[],Table18[],Table110[]),2,0),0) -> 2000000 | AH13: =AG13-AF13 -> 785000
D14: Quà tặng, hiếu, hỉ | E14: 150000 | G14: 12 | H14: =DATEVALUE(Table8[[#This Row],[STT]]&"/"&$J$1) -> 45992 | I14: =SUMIFS(Table10[SỐ TIỀN],Table10[NGÀY CHI],">="&Table8[[#This Row],[Tháng]],Table10[NGÀY CHI],"<"&H15) -> 0 | J14: =IF(Table8[[#This Row],[Tổng chi tiêu]]<>0,SUMIFS(Table103[SỐ TIỀN],Table103[NGÀY],">="&Table8[[#This Row],[Tháng]],Table103[NGÀY],"<"&H15),NA()) -> #N/A | S14: Các khoản chi tiêu lớn nhất | Y14: =Y13+1 -> 45973 | Z14: =Z13+1 -> 45942 | AA14: =IF(Table13[[#This Row],[Tháng này]]<=$A$4,SUMIFS(Table10[SỐ TIỀN],Table10[NGÀY CHI],Table13[[#This Row],[Tháng này]]),NA()) -> 102000 | AB14: =SUMIFS(Table10[SỐ TIỀN],Table10[NGÀY CHI],Table13[[#This Row],[Tháng trước]]) -> 107000 | AD14: Bạn bè, đồng nghiệp | AE14: Jan | AF14: 375000 | AG14: =IFERROR(VLOOKUP(AD14,_xlfn.VSTACK(Table1[],Table14[],Table16[],Table18[],Table110[]),2,0),0) -> 400000 | AH14: =AG14-AF14 -> 25000
S15: NGÀY CHI | T15: NHÓM CHI TIÊU | U15: LOẠI CHI TIÊU | V15: CHI TIẾT | W15: SỐ TIỀN | Y15: =Y14+1 -> 45974 | Z15: =Z14+1 -> 45943 | AA15: =IF(Table13[[#This Row],[Tháng này]]<=$A$4,SUMIFS(Table10[SỐ TIỀN],Table10[NGÀY CHI],Table13[[#This Row],[Tháng này]]),NA()) -> 155000 | AB15: =SUMIFS(Table10[SỐ TIỀN],Table10[NGÀY CHI],Table13[[#This Row],[Tháng trước]]) -> 500000 | AD15: Bạn bè, đồng nghiệp | AE15: Feb | AF15: 385000 | AG15: =IFERROR(VLOOKUP(AD15,_xlfn.VSTACK(Table1[],Table14[],Table16[],Table18[],Table110[]),2,0),0) -> 400000 | AH15: =AG15-AF15 -> 15000
S16: {=IF(W1="Tất cả",_xlfn._xlws.FILTER(Table10[],Table10[NGÀY CHI]>='Công thức'!A3),_xlfn._xlws.FILTER(Table10[],(Table10[NGÀY CHI]>='Công thức'!A3)*(Table10[NHÓM CHI TIÊU]='Công thức'!W1),"Không có dữ liệu"))} -> 45962 | T16: Chi phí thiết yếu | U16: Nhà ở | V16: Nhà ở | W16: 500000 | Y16: =Y15+1 -> 45975 | Z16: =Z15+1 -> 45944 | AA16: =IF(Table13[[#This Row],[Tháng này]]<=$A$4,SUMIFS(Table10[SỐ TIỀN],Table10[NGÀY CHI],Table13[[#This Row],[Tháng này]]),NA()) -> 553000 | AB16: =SUMIFS(Table10[SỐ TIỀN],Table10[NGÀY CHI],Table13[[#This Row],[Tháng trước]]) -> 58000 | AD16: Bạn bè, đồng nghiệp | AE16: Mar | AF16: 602000 | AG16: =IFERROR(VLOOKUP(AD16,_xlfn.VSTACK(Table1[],Table14[],Table16[],Table18[],Table110[]),2,0),0) -> 400000 | AH16: =AG16-AF16 -> -202000
S17: 45975 | T17: Chi phí thiết yếu | U17: Nhà ở | V17: Nhà ở | W17: 500000 | Y17: =Y16+1 -> 45976 | Z17: =Z16+1 -> 45945 | AA17: =IF(Table13[[#This Row],[Tháng này]]<=$A$4,SUMIFS(Table10[SỐ TIỀN],Table10[NGÀY CHI],Table13[[#This Row],[Tháng này]]),NA()) -> 153000 | AB17: =SUMIFS(Table10[SỐ TIỀN],Table10[NGÀY CHI],Table13[[#This Row],[Tháng trước]]) -> 164000 | AD17: Bạn bè, đồng nghiệp | AE17: Apr | AF17: 399000 | AG17: =IFERROR(VLOOKUP(AD17,_xlfn.VSTACK(Table1[],Table14[],Table16[],Table18[],Table110[]),2,0),0) -> 400000 | AH17: =AG17-AF17 -> 1000
S18: 45962 | T18: Chi phí thiết yếu | U18: Hóa đơn hàng tháng | V18: Tiền rác | W18: 35000 | Y18: =Y17+1 -> 45977 | Z18: =Z17+1 -> 45946 | AA18: =IF(Table13[[#This Row],[Tháng này]]<=$A$4,SUMIFS(Table10[SỐ TIỀN],Table10[NGÀY CHI],Table13[[#This Row],[Tháng này]]),NA()) -> 448000 | AB18: =SUMIFS(Table10[SỐ TIỀN],Table10[NGÀY CHI],Table13[[#This Row],[Tháng trước]]) -> 192000 | AD18: Bạn bè, đồng nghiệp | AE18: May | AF18: 411000 | AG18: =IFERROR(VLOOKUP(AD18,_xlfn.VSTACK(Table1[],Table14[],Table16[],Table18[],Table110[]),2,0),0) -> 400000 | AH18: =AG18-AF18 -> -11000
S19: 45963 | T19: Chi phí thiết yếu | U19: Hóa đơn hàng tháng | V19: Tiền nước | W19: 98000 | Y19: =Y18+1 -> 45978 | Z19: =Z18+1 -> 45947 | AA19: =IF(Table13[[#This Row],[Tháng này]]<=$A$4,SUMIFS(Table10[SỐ TIỀN],Table10[NGÀY CHI],Table13[[#This Row],[Tháng này]]),NA()) -> 133000 | AB19: =SUMIFS(Table10[SỐ TIỀN],Table10[NGÀY CHI],Table13[[#This Row],[Tháng trước]]) -> 133000 | AD19: Bạn bè, đồng nghiệp | AE19: Jun | AF19: 443000 | AG19: =IFERROR(VLOOKUP(AD19,_xlfn.VSTACK(Table1[],Table14[],Table16[],Table18[],Table110[]),2,0),0) -> 400000 | AH19: =AG19-AF19 -> -43000
S20: 45963 | T20: Chi phí cá nhân | U20: Học tập, phát triển | V20: Mua sách kế toán doanh nghiệp | W20: 292000 | Y20: =Y19+1 -> 45979 | Z20: =Z19+1 -> 45948 | AA20: =IF(Table13[[#This Row],[Tháng này]]<=$A$4,SUMIFS(Table10[SỐ TIỀN],Table10[NGÀY CHI],Table13[[#This Row],[Tháng này]]),NA()) -> 233000 | AB20: =SUMIFS(Table10[SỐ TIỀN],Table10[NGÀY CHI],Table13[[#This Row],[Tháng trước]]) -> 563000 | AD20: Bạn bè, đồng nghiệp | AE20: Jul | AF20: 452000 | AG20: =IFERROR(VLOOKUP(AD20,_xlfn.VSTACK(Table1[],Table14[],Table16[],Table18[],Table110[]),2,0),0) -> 400000 | AH20: =AG20-AF20 -> -52000
S21: 45963 | T21: Giải trí và xã hội | U21: Bạn bè, đồng nghiệp | V21: Cà phê | W21: 59000 | Y21: =Y20+1 -> 45980 | Z21: =Z20+1 -> 45949 | AA21: =IF(Table13[[#This Row],[Tháng này]]<=$A$4,SUMIFS(Table10[SỐ TIỀN],Table10[NGÀY CHI],Table13[[#This Row],[Tháng này]]),NA()) -> 100000 | AB21: =SUMIFS(Table10[SỐ TIỀN],Table10[NGÀY CHI],Table13[[#This Row],[Tháng trước]]) -> 106000 | AD21: Bạn bè, đồng nghiệp | AE21: Aug | AF21: 446000 | AG21: =IFERROR(VLOOKUP(AD21,_xlfn.VSTACK(Table1[],Table14[],Table16[],Table18[],Table110[]),2,0),0) -> 400000 | AH21: =AG21-AF21 -> -46000
S22: 45964 | T22: Chi phí thiết yếu | U22: Hóa đơn hàng tháng | V22: Tiền điện | W22: 409000 | Y22: =Y21+1 -> 45981 | Z22: =Z21+1 -> 45950 | AA22: =IF(Table13[[#This Row],[Tháng này]]<=$A$4,SUMIFS(Table10[SỐ TIỀN],Table10[NGÀY CHI],Table13[[#This Row],[Tháng này]]),NA()) -> 151000 | AB22: =SUMIFS(Table10[SỐ TIỀN],Table10[NGÀY CHI],Table13[[#This Row],[Tháng trước]]) -> 157000 | AD22: Bạn bè, đồng nghiệp | AE22: Sep | AF22: 437000 | AG22: =IFERROR(VLOOKUP(AD22,_xlfn.VSTACK(Table1[],Table14[],Table16[],Table18[],Table110[]),2,0),0) -> 400000 | AH22: =AG22-AF22 -> -37000
S23: 45979 | T23: Chi phí thiết yếu | U23: Hóa đơn hàng tháng | V23: Tiền mạng internet | W23: 171000 | Y23: =Y22+1 -> 45982 | Z23: =Z22+1 -> 45951 | AA23: =IF(Table13[[#This Row],[Tháng này]]<=$A$4,SUMIFS(Table10[SỐ TIỀN],Table10[NGÀY CHI],Table13[[#This Row],[Tháng này]]),NA()) -> 500000 | AB23: =SUMIFS(Table10[SỐ TIỀN],Table10[NGÀY CHI],Table13[[#This Row],[Tháng trước]]) -> 141000 | AD23: Bạn bè, đồng nghiệp | AE23: Oct | AF23: 416000 | AG23: =IFERROR(VLOOKUP(AD23,_xlfn.VSTACK(Table1[],Table14[],Table16[],Table18[],Table110[]),2,0),0) -> 400000 | AH23: =AG23-AF23 -> -16000
S24: 45964 | T24: Chi phí thiết yếu | U24: Đi lại | V24: Đổ xăng | W24: 46000 | Y24: =Y23+1 -> 45983 | Z24: =Z23+1 -> 45952 | AA24: =IF(Table13[[#This Row],[Tháng này]]<=$A$4,SUMIFS(Table10[SỐ TIỀN],Table10[NGÀY CHI],Table13[[#This Row],[Tháng này]]),NA()) -> 300000 | AB24: =SUMIFS(Table10[SỐ TIỀN],Table10[NGÀY CHI],Table13[[#This Row],[Tháng trước]]) -> 109000 | AD24: Bạn bè, đồng nghiệp | AE24: Nov | AF24: 399000 | AG24: =IFERROR(VLOOKUP(AD24,_xlfn.VSTACK(Table1[],Table14[],Table16[],Table18[],Table110[]),2,0),0) -> 400000 | AH24: =AG24-AF24 -> 1000
S25: 45964 | T25: Chi phí cá nhân | U25: Ăn uống | V25: Đi chợ | W25: 140000 | Y25: =Y24+1 -> 45984 | Z25: =Z24+1 -> 45953 | AA25: =IF(Table13[[#This Row],[Tháng này]]<=$A$4,SUMIFS(Table10[SỐ TIỀN],Table10[NGÀY CHI],Table13[[#This Row],[Tháng này]]),NA()) -> #N/A | AB25: =SUMIFS(Table10[SỐ TIỀN],Table10[NGÀY CHI],Table13[[#This Row],[Tháng trước]]) -> 513000 | AD25: Đầu tư | AE25: Jan | AF25: 1000000 | AG25: =IFERROR(VLOOKUP(AD25,_xlfn.VSTACK(Table1[],Table14[],Table16[],Table18[],Table110[]),2,0),0) -> 1000000 | AH25: =AG25-AF25 -> 0
S26: 45977 | T26: Giải trí và xã hội | U26: Mua sắm | V26: Quần mới | W26: 271000 | Y26: =Y25+1 -> 45985 | Z26: =Z25+1 -> 45954 | AA26: =IF(Table13[[#This Row],[Tháng này]]<=$A$4,SUMIFS(Table10[SỐ TIỀN],Table10[NGÀY CHI],Table13[[#This Row],[Tháng này]]),NA()) -> #N/A | AB26: =SUMIFS(Table10[SỐ TIỀN],Table10[NGÀY CHI],Table13[[#This Row],[Tháng trước]]) -> 226000 | AD26: Đầu tư | AE26: Feb | AF26: 1000000 | AG26: =IFERROR(VLOOKUP(AD26,_xlfn.VSTACK(Table1[],Table14[],Table16[],Table18[],Table110[]),2,0),0) -> 1000000 | AH26: =AG26-AF26 -> 0
S27: 45965 | T27: Tiết kiệm, đầu tư | U27: Tiết kiệm | V27: Gửi tiết kiệm | W27: 500000 | Y27: =Y26+1 -> 45986 | Z27: =Z26+1 -> 45955 | AA27: =IF(Table13[[#This Row],[Tháng này]]<=$A$4,SUMIFS(Table10[SỐ TIỀN],Table10[NGÀY CHI],Table13[[#This Row],[Tháng này]]),NA()) -> #N/A | AB27: =SUMIFS(Table10[SỐ TIỀN],Table10[NGÀY CHI],Table13[[#This Row],[Tháng trước]]) -> 193000 | AD27: Đầu tư | AE27: Mar | AF27: 1000000 | AG27: =IFERROR(VLOOKUP(AD27,_xlfn.VSTACK(Table1[],Table14[],Table16[],Table18[],Table110[]),2,0),0) -> 1000000 | AH27: =AG27-AF27 -> 0
S28: 45965 | T28: Chi phí cá nhân | U28: Ăn uống | V28: Đi chợ | W28: 95000 | Y28: =Y27+1 -> 45987 | Z28: =Z27+1 -> 45956 | AA28: =IF(Table13[[#This Row],[Tháng này]]<=$A$4,SUMIFS(Table10[SỐ TIỀN],Table10[NGÀY CHI],Table13[[#This Row],[Tháng này]]),NA()) -> #N/A | AB28: =SUMIFS(Table10[SỐ TIỀN],Table10[NGÀY CHI],Table13[[#This Row],[Tháng trước]]) -> 500000 | AD28: Đầu tư | AE28: Apr | AF28: 2000000 | AG28: =IFERROR(VLOOKUP(AD28,_xlfn.VSTACK(Table1[],Table14[],Table16[],Table18[],Table110[]),2,0),0) -> 1000000 | AH28: =AG28-AF28 -> -1000000
... S30: 45966 | T30: Chi phí cá nhân | U30: Sức khỏe, làm đẹp | V30: Sữa rửa mặt | W30: 80000 | Y30: =Y29+1 -> 45989 | Z30: =Z29+1 -> 45958 | AA30: =IF(Table13[[#This Row],[Tháng này]]<=$A$4,SUMIFS(Table10[SỐ TIỀN],Table10[NGÀY CHI],Table13[[#This Row],[Tháng này]]),NA()) -> #N/A | AB30: =SUMIFS(Table10[SỐ TIỀN],Table10[NGÀY CHI],Table13[[#This Row],[Tháng trước]]) -> 149000 | AD30: Đầu tư | AE30: Jun | AF30: 1000000 | AG30: =IFERROR(VLOOKUP(AD30,_xlfn.VSTACK(Table1[],Table14[],Table16[],Table18[],Table110[]),2,0),0) -> 1000000 | AH30: =AG30-AF30 -> 0
S31: 45966 | T31: Chi phí cá nhân | U31: Ăn uống | V31: Đi chợ | W31: 102000 | Y31: =IF(Y30+1<=EOMONTH($A$3,0),Y30+1,"") -> 45990 | Z31: =IF(Z30+1<=$B$4,Z30+1,"") -> 45959 | AA31: =IF(Table13[[#This Row],[Tháng này]]<=$A$4,SUMIFS(Table10[SỐ TIỀN],Table10[NGÀY CHI],Table13[[#This Row],[Tháng này]]),NA()) -> #N/A | AB31: =SUMIFS(Table10[SỐ TIỀN],Table10[NGÀY CHI],Table13[[#This Row],[Tháng trước]]) -> 164000 | AD31: Đầu tư | AE31: Jul | AF31: 3000000 | AG31: =IFERROR(VLOOKUP(AD31,_xlfn.VSTACK(Table1[],Table14[],Table16[],Table18[],Table110[]),2,0),0) -> 1000000 | AH31: =AG31-AF31 -> -2000000
S32: 45966 | T32: Giải trí và xã hội | U32: Bạn bè, đồng nghiệp | V32: Cà phê | W32: 63000 | Y32: =IF(Y31+1<=EOMONTH($A$3,0),Y31+1,"") -> 45991 | Z32: =IF(Z31+1<=$B$4,Z31+1,"") -> 45960 | AA32: =IF(Table13[[#This Row],[Tháng này]]<=$A$4,SUMIFS(Table10[SỐ TIỀN],Table10[NGÀY CHI],Table13[[#This Row],[Tháng này]]),NA()) -> #N/A | AB32: =SUMIFS(Table10[SỐ TIỀN],Table10[NGÀY CHI],Table13[[#This Row],[Tháng trước]]) -> 197000 | AD32: Đầu tư | AE32: Aug | AF32: 1000000 | AG32: =IFERROR(VLOOKUP(AD32,_xlfn.VSTACK(Table1[],Table14[],Table16[],Table18[],Table110[]),2,0),0) -> 1000000 | AH32: =AG32-AF32 -> 0
S33: 45967 | T33: Giải trí và xã hội | U33: Du lịch | V33: Quỹ du lịch | W33: 500000 | Y33: =IF(Y32+1<=EOMONTH($A$3,0),Y32+1,"") | Z33: =IF(Z32+1<=$B$4,Z32+1,"") -> 45961 | AA33: =IF(Table13[[#This Row],[Tháng này]]<=$A$4,SUMIFS(Table10[SỐ TIỀN],Table10[NGÀY CHI],Table13[[#This Row],[Tháng này]]),NA()) -> #N/A | AB33: =SUMIFS(Table10[SỐ TIỀN],Table10[NGÀY CHI],Table13[[#This Row],[Tháng trước]]) -> 0 | AD33: Đầu tư | AE33: Sep | AF33: 1000000 | AG33: =IFERROR(VLOOKUP(AD33,_xlfn.VSTACK(Table1[],Table14[],Table16[],Table18[],Table110[]),2,0),0) -> 1000000 | AH33: =AG33-AF33 -> 0
S34: 45967 | T34: Giải trí và xã hội | U34: Mua sắm | V34: Mua tất | W34: 47000 | AD34: Đầu tư | AE34: Oct | AF34: 1000000 | AG34: =IFERROR(VLOOKUP(AD34,_xlfn.VSTACK(Table1[],Table14[],Table16[],Table18[],Table110[]),2,0),0) -> 1000000 | AH34: =AG34-AF34 -> 0
S35: 45968 | T35: Chi phí thiết yếu | U35: Đi lại | V35: Đổ xăng | W35: 49000 | AD35: Đầu tư | AE35: Nov | AF35: 1000000 | AG35: =IFERROR(VLOOKUP(AD35,_xlfn.VSTACK(Table1[],Table14[],Table16[],Table18[],Table110[]),2,0),0) -> 1000000 | AH35: =AG35-AF35 -> 0
S36: 45968 | T36: Chi phí thiết yếu | U36: Đi lại | V36: Thay dầu | W36: 94000 | AD36: Đi lại | AE36: Jan | AF36: 570000 | AG36: =IFERROR(VLOOKUP(AD36,_xlfn.VSTACK(Table1[],Table14[],Table16[],Table18[],Table110[]),2,0),0) -> 600000 | AH36: =AG36-AF36 -> 30000
S37: 45968 | T37: Chi phí thiết yếu | U37: Đi lại | V37: Rửa xe | W37: 18000 | AD37: Đi lại | AE37: Feb | AF37: 530000 | AG37: =IFERROR(VLOOKUP(AD37,_xlfn.VSTACK(Table1[],Table14[],Table16[],Table18[],Table110[]),2,0),0) -> 600000 | AH37: =AG37-AF37 -> 70000
S38: 45968 | T38: Chi phí cá nhân | U38: Ăn uống | V38: Đi chợ | W38: 94000 | AD38: Đi lại | AE38: Mar | AF38: 818000 | AG38: =IFERROR(VLOOKUP(AD38,_xlfn.VSTACK(Table1[],Table14[],Table16[],Table18[],Table110[]),2,0),0) -> 600000 | AH38: =AG38-AF38 -> -218000
S39: 45968 | T39: Giải trí và xã hội | U39: Giải trí | V39: đi xem phim | W39: 190000 | AD39: Đi lại | AE39: Apr | AF39: 666000 | AG39: =IFERROR(VLOOKUP(AD39,_xlfn.VSTACK(Table1[],Table14[],Table16[],Table18[],Table110[]),2,0),0) -> 600000 | AH39: =AG39-AF39 -> -66000
S40: 45969 | T40: Tiết kiệm, đầu tư | U40: Đầu tư | V40: Mua cổ phiếu | W40: 500000 | AD40: Đi lại | AE40: May | AF40: 670000 | AG40: =IFERROR(VLOOKUP(AD40,_xlfn.VSTACK(Table1[],Table14[],Table16[],Table18[],Table110[]),2,0),0) -> 600000 | AH40: =AG40-AF40 -> -70000
S41: 45971 | T41: Tiết kiệm, đầu tư | U41: Đầu tư | V41: Mua cổ phiếu | W41: 500000 | AD41: Đi lại | AE41: Jun | AF41: 678000 | AG41: =IFERROR(VLOOKUP(AD41,_xlfn.VSTACK(Table1[],Table14[],Table16[],Table18[],Table110[]),2,0),0) -> 600000 | AH41: =AG41-AF41 -> -78000
...

Sheet Chi tiêu
B2: Bảng Nhật Kí Chi Tiêu Cá Nhân & Gia Đình
B3: Các khoản chi tiêu hàng ngày
C5: NGÀY CHI | D5: NHÓM CHI TIÊU | E5: LOẠI CHI TIÊU | F5: CHI TIẾT | G5: SỐ TIỀN
C6: 45658 | D6: Chi phí thiết yếu | E6: Nhà ở | F6: Nhà ở | G6: 1600000
C7: 45658 | D7: Chi phí thiết yếu | E7: Hóa đơn hàng tháng | F7: Tiền rác | G7: 30000
C8: 45659 | D8: Chi phí thiết yếu | E8: Hóa đơn hàng tháng | F8: Tiền điện | G8: 400000
C9: 45659 | D9: Chi phí thiết yếu | E9: Hóa đơn hàng tháng | F9: Tiền nước | G9: 100000
C10: 45659 | D10: Chi phí cá nhân | E10: Học tập, phát triển | F10: Mua sách kế toán doanh nghiệp | G10: 350000
C11: 45659 | D11: Giải trí và xã hội | E11: Bạn bè, đồng nghiệp | F11: Cà phê | G11: 50000
C12: 45660 | D12: Chi phí thiết yếu | E12: Hóa đơn hàng tháng | F12: Tiền mạng internet | G12: 200000
C13: 45660 | D13: Chi phí thiết yếu | E13: Đi lại | F13: Đổ xăng | G13: 50000
C14: 45660 | D14: Chi phí cá nhân | E14: Ăn uống | F14: Đi chợ | G14: 165000
C15: 45660 | D15: Giải trí và xã hội | E15: Mua sắm | F15: Quần mới | G15: 220000
C16: 45660 | D16: Tiết kiệm, đầu tư | E16: Tiết kiệm | F16: Gửi tiết kiệm | G16: 500000
C17: 45661 | D17: Chi phí cá nhân | E17: Ăn uống | F17: Đi chợ | G17: 105000
... C621: 45983 | D621: Quà tặng, hiếu, hỉ | E621: Quà tặng | F621: Quà tặng người yêu | G621: 300000

Sheet Thu nhập
B2: Bảng Nhật Kí Các Nguồn Thu Nhập Cá Nhân Và Gia Đình
B3: Các khoản thu nhập hàng tháng
C5: NGÀY | D5: LOẠI THU NHẬP | E5: CHI TIẾT | F5: SỐ TIỀN
C6: 45658 | D6: Lương | E6: Lương tháng 1 | F6: 9000000
C7: 45658 | D7: Thưởng | E7: Thưởng KPI tháng 1 | F7: 900000
C8: 45689 | D8: Lương | E8: Lương tháng 2 | F8: 9000000
C9: 45689 | D9: Thưởng | E9: Thưởng KPI tháng 2 | F9: 2100000
C10: 45717 | D10: Lương | E10: Lương tháng 3 | F10: 9000000
C11: 45717 | D11: Thưởng | E11: Thưởng KPI tháng 3 | F11: 1000000
C12: 45748 | D12: Lương | E12: Lương tháng 4 | F12: 9000000
C13: 45748 | D13: Thưởng | E13: Thưởng KPI tháng 4 | F13: 3100000
C14: 45778 | D14: Lương | E14: Lương tháng 5 | F14: 9000000
C15: 45778 | D15: Thưởng | E15: Thưởng KPI tháng 5 | F15: 1000000
C16: 45809 | D16: Lương | E16: Lương tháng 6 | F16: 9000000
C17: 45809 | D17: Thưởng | E17: Thưởng KPI tháng 6 | F17: 2200000
... C27: 45962 | D27: Thưởng | E27: Thưởng KPI tháng 11 | F27: 1000000

Sheet Định mức
B1: Chi phí thiết yếu | E1: Chi phí cá nhân | H1: Giải trí và xã hội | K1: Tiết kiệm, đầu tư | N1: Quà tặng, hiếu, hỉ
B2: Loại chi tiêu | C2: Định mức | E2: Loại chi tiêu | F2: Định mức | H2: Loại chi tiêu | I2: Định mức | K2: Loại chi tiêu | L2: Định mức | N2: Loại chi tiêu | O2: Định mức
B3: Nhà ở | C3: 1600000 | E3: Ăn uống | F3: 2000000 | H3: Du lịch | I3: 500000 | K3: Tiết kiệm | L3: 500000 | N3: Quà tặng | O3: 300000
B4: Hóa đơn hàng tháng | C4: 800000 | E4: Học tập, phát triển | F4: 500000 | H4: Giải trí | I4: 500000 | K4: Đầu tư | L4: 1000000 | N4: Hiếu, hỉ | O4: 500000
B5: Đi lại | C5: 600000 | E5: Sức khỏe, làm đẹp | F5: 300000 | H5: Bạn bè, đồng nghiệp | I5: 400000
H6: Mua sắm | I6: 500000
B13: Tổng | C13: =SUBTOTAL(9,Table1[Định mức]) -> 3000000 | E13: Tổng | F13: =SUBTOTAL(9,Table14[Định mức]) -> 2800000 | H13: Tổng | I13: =SUBTOTAL(9,Table16[Định mức]) -> 1900000 | K13: Tổng | L13: =SUBTOTAL(9,Table18[Định mức]) -> 1500000 | N13: Tổng | O13: =SUBTOTAL(9,Table110[Định mức]) -> 800000
B31: =$B$1 -> Chi phí thiết yếu | C31: =B3 -> Nhà ở | E31: {=_xlfn.CHOOSECOLS(B31:C78,1)} -> Chi phí thiết yếu | F31: {=_xlfn.CHOOSECOLS(B31:C78,2)} -> Nhà ở
B32: =$B$1 -> Chi phí thiết yếu | C32: =B4 -> Hóa đơn hàng tháng | E32: Chi phí thiết yếu | F32: Hóa đơn hàng tháng
B33: =$B$1 -> Chi phí thiết yếu | C33: =B5 -> Đi lại | E33: Chi phí thiết yếu | F33: Đi lại
B34: =$B$1 -> Chi phí thiết yếu | C34: =B6 -> 0 | E34: Chi phí thiết yếu | F34: 0
B35: =$B$1 -> Chi phí thiết yếu | C35: =B7 -> 0 | E35: Chi phí thiết yếu | F35: 0
B36: =$B$1 -> Chi phí thiết yếu | C36: =B8 -> 0 | E36: Chi phí thiết yếu | F36: 0
B37: =$B$1 -> Chi phí thiết yếu | C37: =B9 -> 0 | E37: Chi phí thiết yếu | F37: 0
B38: =$B$1 -> Chi phí thiết yếu | C38: =B10 -> 0 | E38: Chi phí thiết yếu | F38: 0
B39: =$B$1 -> Chi phí thiết yếu | C39: =B11 -> 0 | E39: Chi phí thiết yếu | F39: 0
B40: =$B$1 -> Chi phí thiết yếu | C40: =B12 -> 0 | E40: Chi phí thiết yếu | F40: 0
B41: =$E$1 -> Chi phí cá nhân | C41: =E3 -> Ăn uống | E41: Chi phí cá nhân | F41: Ăn uống
B42: =$E$1 -> Chi phí cá nhân | C42: =E4 -> Học tập, phát triển | E42: Chi phí cá nhân | F42: Học tập, phát triển
B43: =$E$1 -> Chi phí cá nhân | C43: =E5 -> Sức khỏe, làm đẹp | E43: Chi phí cá nhân | F43: Sức khỏe, làm đẹp
B44: =$E$1 -> Chi phí cá nhân | C44: =E6 -> 0 | E44: Chi phí cá nhân | F44: 0
B45: =$E$1 -> Chi phí cá nhân | C45: =E7 -> 0 | E45: Chi phí cá nhân | F45: 0
B46: =$E$1 -> Chi phí cá nhân | C46: =E8 -> 0 | E46: Chi phí cá nhân | F46: 0
B47: =$E$1 -> Chi phí cá nhân | C47: =E9 -> 0 | E47: Chi phí cá nhân | F47: 0
B48: =$E$1 -> Chi phí cá nhân | C48: =E10 -> 0 | E48: Chi phí cá nhân | F48: 0
B49: =$E$1 -> Chi phí cá nhân | C49: =E11 -> 0 | E49: Chi phí cá nhân | F49: 0
B50: =$H$1 -> Giải trí và xã hội | C50: =H3 -> Du lịch | E50: Giải trí và xã hội | F50: Du lịch
B51: =$H$1 -> Giải trí và xã hội | C51: =H4 -> Giải trí | E51: Giải trí và xã hội | F51: Giải trí
B52: =$H$1 -> Giải trí và xã hội | C52: =H5 -> Bạn bè, đồng nghiệp | E52: Giải trí và xã hội | F52: Bạn bè, đồng nghiệp
B53: =$H$1 -> Giải trí và xã hội | C53: =H6 -> Mua sắm | E53: Giải trí và xã hội | F53: Mua sắm
B54: =$H$1 -> Giải trí và xã hội | C54: =H7 -> 0 | E54: Giải trí và xã hội | F54: 0
B55: =$H$1 -> Giải trí và xã hội | C55: =H8 -> 0 | E55: Giải trí và xã hội | F55: 0
B56: =$H$1 -> Giải trí và xã hội | C56: =H9 -> 0 | E56: Giải trí và xã hội | F56: 0
B57: =$H$1 -> Giải trí và xã hội | C57: =H10 -> 0 | E57: Giải trí và xã hội | F57: 0
B58: =$H$1 -> Giải trí và xã hội | C58: =H11 -> 0 | E58: Giải trí và xã hội | F58: 0
B59: =$K$1 -> Tiết kiệm, đầu tư | C59: =K3 -> Tiết kiệm | E59: Tiết kiệm, đầu tư | F59: Tiết kiệm
B60: =$K$1 -> Tiết kiệm, đầu tư | C60: =K4 -> Đầu tư | E60: Tiết kiệm, đầu tư | F60: Đầu tư
B61: =$K$1 -> Tiết kiệm, đầu tư | C61: =K5 -> 0 | E61: Tiết kiệm, đầu tư | F61: 0
B62: =$K$1 -> Tiết kiệm, đầu tư | C62: =K6 -> 0 | E62: Tiết kiệm, đầu tư | F62: 0
B63: =$K$1 -> Tiết kiệm, đầu tư | C63: =K7 -> 0 | E63: Tiết kiệm, đầu tư | F63: 0
...

Sheet Color
B3: Background | C3: #CCECFF | D3: #85D1FF | E3: #26ACAF
C5: #AB3DC4 | D5: #821798
C6: #0CB1F1 | D6: #0A9ECD | E6: #0186EB
C7: #1FD7A5 | D7: #14BC89 | E7: #33CAC8
C8: #F8BC2F | D8: #FEB81A | E8: #FF9614 | F8: #F88032
C9: #EC3957 | D9: #CF1D3F

Sheet Hàm sử dụng
B2: Hàm xử lý ngày tháng | C2: Hàm xử lý mảng | D2: Hàm thông dụng | E2: Công cụ
B3: DATE() | C3: SORTBY() | D3: SUMIFS() | E3: PIVOT TABLE
B4: YEAR() | C4: TAKE() | D4: IF() | E4: SLICER
B5: MONTH() | C5: UNIQUE() | D5: MAX() | E5: TABLE
B6: DAY() | C6: INDEX() | D6: NA() | E6: CONDITIONAL FORMATTING
B7: DATEVALUE() | C7: VSTACK() | D7: SUBTOTAL()
B8: EOMONTH()
